2024-11-06 23:58:43,765 ERROR: Exception on /update_distribution_list/1 [PUT] [in C:\Users\Jayanth\PycharmProjects\ClearEon_be\venv\Lib\site-packages\flask\app.py:1414]
Traceback (most recent call last):
  File "C:\Users\Jayanth\PycharmProjects\ClearEon_be\venv\Lib\site-packages\flask\app.py", line 2190, in wsgi_app
    response = self.full_dispatch_request()
               ^^^^^^^^^^^^^^^^^^^^^^^^^^^^
  File "C:\Users\Jayanth\PycharmProjects\ClearEon_be\venv\Lib\site-packages\flask\app.py", line 1486, in full_dispatch_request
    rv = self.handle_user_exception(e)
         ^^^^^^^^^^^^^^^^^^^^^^^^^^^^^
  File "C:\Users\Jayanth\PycharmProjects\ClearEon_be\venv\Lib\site-packages\flask_cors\extension.py", line 194, in wrapped_function
    return cors_after_request(app.make_response(f(*args, **kwargs)))
                                                ^^^^^^^^^^^^^^^^^^
  File "C:\Users\Jayanth\PycharmProjects\ClearEon_be\venv\Lib\site-packages\flask\app.py", line 1484, in full_dispatch_request
    rv = self.dispatch_request()
         ^^^^^^^^^^^^^^^^^^^^^^^
  File "C:\Users\Jayanth\PycharmProjects\ClearEon_be\venv\Lib\site-packages\flask\app.py", line 1469, in dispatch_request
    return self.ensure_sync(self.view_functions[rule.endpoint])(**view_args)
           ^^^^^^^^^^^^^^^^^^^^^^^^^^^^^^^^^^^^^^^^^^^^^^^^^^^^^^^^^^^^^^^^^
TypeError: update_distribution_list() got an unexpected keyword argument 'id'
2024-11-08 01:44:26,714 ERROR: Exception on /users [POST] [in C:\Users\Jayanth\PycharmProjects\ClearEon_be\venv\Lib\site-packages\flask\app.py:1414]
Traceback (most recent call last):
  File "C:\Users\Jayanth\PycharmProjects\ClearEon_be\venv\Lib\site-packages\flask\app.py", line 2190, in wsgi_app
    response = self.full_dispatch_request()
               ^^^^^^^^^^^^^^^^^^^^^^^^^^^^
  File "C:\Users\Jayanth\PycharmProjects\ClearEon_be\venv\Lib\site-packages\flask\app.py", line 1486, in full_dispatch_request
    rv = self.handle_user_exception(e)
         ^^^^^^^^^^^^^^^^^^^^^^^^^^^^^
  File "C:\Users\Jayanth\PycharmProjects\ClearEon_be\venv\Lib\site-packages\flask_cors\extension.py", line 194, in wrapped_function
    return cors_after_request(app.make_response(f(*args, **kwargs)))
                                                ^^^^^^^^^^^^^^^^^^
  File "C:\Users\Jayanth\PycharmProjects\ClearEon_be\venv\Lib\site-packages\flask\app.py", line 1484, in full_dispatch_request
    rv = self.dispatch_request()
         ^^^^^^^^^^^^^^^^^^^^^^^
  File "C:\Users\Jayanth\PycharmProjects\ClearEon_be\venv\Lib\site-packages\flask\app.py", line 1469, in dispatch_request
    return self.ensure_sync(self.view_functions[rule.endpoint])(**view_args)
           ^^^^^^^^^^^^^^^^^^^^^^^^^^^^^^^^^^^^^^^^^^^^^^^^^^^^^^^^^^^^^^^^^
  File "C:\Users\Jayanth\PycharmProjects\ClearEon_be\sitecontrols.py", line 43, in create_user
    (str(uuid.uuid4()), data['client_id'], data['role_id'], data['username'], data['email'], data['password_hash'])
                        ~~~~^^^^^^^^^^^^^
KeyError: 'client_id'
